<?xml version="1.0" encoding="utf-8"?>
<robot name="conveyor" xmlns:xacro="http://ros.org/wiki/xacro">

	

	<link name="belt_visual">
		<inertial>
			<origin xyz="1.1327E-16 -3.3286E-17 0.66019" rpy="0 0 0" />
			<mass value="71.953" />
			<inertia ixx="7.5972" ixy="-1.394E-14" ixz="1.9328E-17" iyy="0.99673" iyz="-9.2056E-18" izz="8.1168" />
		</inertial>
		<visual>
			<origin xyz="0 0 0" rpy="0 0 0" />
			<geometry>
				<mesh filename="./meshes/conveyor_belt.stl" scale="1. 4. 0.5"/>
			</geometry>
			<material name="white">
				<color rgba="1 1 1 1" />
			</material>
		</visual>
		<collision>
			<origin xyz="0.0 0.0 0" rpy="1.570796327 0.0 1.570796327"/>
			<geometry>
				<mesh filename="./meshes/conveyor_simple.stl" />
			</geometry>
		</collision>
	</link>

	

	<joint name="belt_joint" type="prismatic">
		<origin xyz="0.0 0.0 0.37" rpy="0.0 0.0 0.0"/>
		<parent link="belt_visual"/>
		<child link="belt_moving"/>
		<axis xyz="0 1 0"/>
		<limit lower="0.0" upper="1" effort="1000" velocity="1000"/>
	</joint>

	<link name="belt_moving">
		<inertial>
			<origin xyz="0.0 0.0 0.0" rpy="0.0 0.0 0.0"/>
			<mass value="100"/>
			<inertia ixx="0.0" ixy="0.0" ixz="0.0" iyy="0.0" iyz="0.0" izz="0.0"/>
		</inertial>

		<visual>
			<origin xyz="0.0 0.0 0.0005" rpy="0.0 0.0 0.0"/>
			<geometry>
				<box size="0.425 4.8 0.001"/>
			</geometry>
			<material name="black">
          		<color rgba="0.4 0.4 0.4 1.0"/>
        	</material>
		</visual>

		<collision>
			<origin xyz="0.0 0.0 0.0005" rpy="0.0 0.0 0.0"/>
			<geometry>
				<box size="0.425 4.8 0.001"/>
			</geometry>
		</collision>
	</link>

</robot>
