<?xml version="1.0" encoding="utf-8"?>
<robot name="dingo-o" xmlns:xacro="http://www.ros.org/wiki/xacro">

  <gazebo>
    <plugin filename="libgazebo_ros_control.so" name="ros_control">
      <!--robotNamespace>/</robotNamespace-->
      <!--robotSimType>gazebo_ros_control/DefaultRobotHWSim</robotSimType-->
    </plugin>
  </gazebo>

  <xacro:property name="PI" value="3.1415926535897931" />

  <xacro:property name="wheelbase" value="0.570" />
  <xacro:property name="track" value="0.3708" />
  <xacro:property name="wheel_vertical_offset" value="0.035145" />

  <xacro:property name="wheel_radius" value="0.050" />
  <xacro:property name="wheel_mass" value="0.4" />
  <xacro:property name="wheel_width" value="0.050" />

  <xacro:property name="dummy_inertia" value="1e-09"/>


  <material name="dark_grey"><color rgba="0.2 0.2 0.2 1.0" /></material>
  <material name="light_grey"><color rgba="0.4 0.4 0.4 1.0" /></material>
  <material name="yellow"><color rgba="0.8 0.8 0.0 1.0" /></material>
  <material name="black"><color rgba="0.15 0.15 0.15 1.0" /></material>

  <xacro:macro name="wheel" params="prefix *joint_pose">

    <link name="${prefix}_wheel_link">
      <visual>
        <origin xyz="0 0 0" rpy="${PI/2} 0 0"/>
        <geometry>
          <cylinder radius="${wheel_radius}" length="${wheel_width}"/>
        </geometry>
        <material name="black" />
      </visual>
      <collision>
        <origin xyz="0 0 0" rpy="${PI/2} 0 0"/>
        <geometry>
          <cylinder radius="${wheel_radius}" length="${wheel_width}"/>
        </geometry>
      </collision>
      <inertial>
        <origin xyz="0 0 0" rpy="0 0 0"/>
        <mass value="${wheel_mass}"/>
        <inertia
          ixx="0.0003234" ixy="0" ixz="0"
          iyy="0.0003234" iyz="0"
          izz="0.0004901"/>
      </inertial>
    </link>

    <joint name="${prefix}_wheel" type="continuous">
      <parent link="chassis_link"/>
      <child link="${prefix}_wheel_link" />
      <xacro:insert_block name="joint_pose" />
      <axis xyz="0 1 0" />
    </joint>

    <transmission name="${prefix}_wheel_trans">
      <type>transmission_interface/SimpleTransmission</type>
      <joint name="${prefix}_wheel">
        <hardwareInterface>hardware_interface/VelocityJointInterface</hardwareInterface>
      </joint>
      <actuator name="${prefix}_actuator">
        <mechanicalReduction>1</mechanicalReduction>
      </actuator>
    </transmission>
  </xacro:macro>

  <xacro:wheel prefix="front_left">
    <origin xyz="${wheelbase/2} ${track/2+wheel_width/2} ${wheel_vertical_offset}" rpy="0 0 0" />
  </xacro:wheel>
  <xacro:wheel prefix="front_right">
    <origin xyz="${wheelbase/2} ${-track/2-wheel_width/2} ${wheel_vertical_offset}" rpy="0 0 0" />
  </xacro:wheel>
  <xacro:wheel prefix="rear_left">
    <origin xyz="${-wheelbase/2} ${track/2+wheel_width/2} ${wheel_vertical_offset}" rpy="0 0 0" />
  </xacro:wheel>
  <xacro:wheel prefix="rear_right">
    <origin xyz="${-wheelbase/2} ${-track/2-wheel_width/2} ${wheel_vertical_offset}" rpy="0 0 0" />
  </xacro:wheel>

  <link name="base_link"></link>

  <joint name="base_link_joint" type="fixed">
    <origin xyz="0 0 0" rpy="0 0 0" />
    <parent link="base_link"/>
    <child link="chassis_link" />
  </joint>

  <link name="chassis_link">
    <visual>
      <origin xyz="0 0 0" rpy="0 0 0"/>
      <geometry>
        <mesh filename="meshes/omni_chassis.dae"/>
      </geometry>
      <material name="yellow" />
    </visual>
    <collision>
      <origin xyz="0 0 0"/>
      <geometry>
        <mesh filename="meshes/omni_chassis_collision.stl"/>
      </geometry>
    </collision>
    <inertial>
      <!-- Center of mass -->
      <origin xyz="0 0 0" rpy="0 0 0"/>
      <mass value="14"/>
      <!-- Moments of inertia: ( chassis without wheels ) -->
      <inertia
        ixx="0.35498" ixy="0" ixz="0"
        iyy="0.7266" iyz="0"
        izz="1.0553"/>
      </inertial>
  </link>

  <gazebo reference="front_left_wheel_link">
    <material>Gazebo/DarkGrey</material>
    <mu1>0.0</mu1>
    <mu2>0.0</mu2>
  </gazebo>

  <gazebo reference="front_right_wheel_link">
    <material>Gazebo/DarkGrey</material>
    <mu1>0.0</mu1>
    <mu2>0.0</mu2>
  </gazebo>

  <gazebo reference="rear_left_wheel_link">
    <material>Gazebo/DarkGrey</material>
    <mu1>0.0</mu1>
    <mu2>0.0</mu2>
  </gazebo>

  <gazebo reference="rear_right_wheel_link">
    <material>Gazebo/DarkGrey</material>
    <mu1>0.0</mu1>
    <mu2>0.0</mu2>
  </gazebo>


  
</robot>
