<?xml version="1.0"?>
<robot name="ur5e" xmlns:xacro="http://ros.org/wiki/xacro">
    <link name="ur5_base_link" >
      <visual>
        <geometry>
          <mesh filename="./meshes/ur5e/visual/base.dae" />
        </geometry>
        <material name="LightGrey">
          <color rgba="0.7 0.7 0.7 1.0"/>
        </material>
      </visual>
      <collision>
        <geometry>
          <mesh filename="./meshes/ur5e/collision/base.stl" />
        </geometry>
      </collision>
      <inertial>
        <mass value="4.0" />
        <origin xyz="0.0 0.0 0.0" rpy="0 0 0" />
        <inertia ixx="0.0044333" ixy="0.0" ixz="0.0"
        iyy="0.0044333" iyz="0.0"
        izz="0.0072" />
      </inertial>
    </link>

    <joint name="ur5_shoulder_pan_joint" type="revolute">
      <parent link="ur5_base_link" />
      <child link = "ur5_shoulder_link" />
      <origin xyz="0.0 0.0 0.163" rpy="0.0 0.0 0.0" />
      <axis xyz="0 0 1" />
      <limit lower="-6.28" upper="6.28" effort="150.0" velocity="3.14"/>
    </joint>

    <link name="ur5_shoulder_link">
      <visual>
        <geometry>
          <mesh filename="./meshes/ur5e/visual/shoulder.dae" />
        </geometry>
        <material name="LightGrey">
          <color rgba="0.7 0.7 0.7 1.0"/>
        </material>
      </visual>
      <collision>
        <geometry>
          <mesh filename="./meshes/ur5e/collision/shoulder.stl" />
        </geometry>
      </collision>
      <inertial>
      <origin xyz="0.0 0.0 0.0" rpy="0 0 0" />
      <mass value="3.7000" />
      <inertia ixx="0.0102675" ixy="0.0" ixz="0.0"
        iyy="0.0102675" iyz="0.0"
        izz="0.00666" />
      </inertial>
    </link>

    <joint name="ur5_shoulder_lift_joint" type="revolute">
      <parent link="ur5_shoulder_link" />
      <child link = "ur5_upper_arm_link" />
      <origin xyz="0.0 0.138 0.0" rpy="0.0 1.570795 0.0" />
      <axis xyz="0 1 0" />
      <limit lower="-1.57" upper="1.57" effort="150.0" velocity="3.14"/>
    </joint>

    <link name="ur5_upper_arm_link">
      <visual>
        <geometry>
          <mesh filename="./meshes/ur5e/visual/upperarm.dae" />
        </geometry>
        <material name="LightGrey">
          <color rgba="0.7 0.7 0.7 1.0"/>
        </material>
      </visual>
      <collision>
        <geometry>
          <mesh filename="./meshes/ur5e/collision/upperarm.stl" />
        </geometry>
      </collision>
      <inertial>
      <origin xyz="0.0 0.0 0.2125" rpy="0 0 0" />
      <mass value="3.7000" />
      <inertia ixx="0.1338858" ixy="0.0" ixz="0.0"
        iyy="0.1338858" iyz="0.0"
        izz="0.0151074" />
      </inertial>
    </link>

    <joint name="ur5_elbow_joint" type="revolute">
      <parent link="ur5_upper_arm_link" />
      <child link = "ur5_forearm_link" />
      <origin xyz="0.0 -0.131 0.425" rpy="0.0 0.0 0.0" />
      <axis xyz="0 1 0" />
      <limit lower="-3.14" upper="3.14" effort="150.0" velocity="3.14"/>
    </joint>

    <link name="ur5_forearm_link">
      <visual>
        <geometry>
          <mesh filename="./meshes/ur5e/visual/forearm.dae" />
        </geometry>
        <material name="LightGrey">
          <color rgba="0.7 0.7 0.7 1.0"/>
        </material>
      </visual>
      <collision>
        <geometry>
          <mesh filename="./meshes/ur5e/collision/forearm.stl" />
        </geometry>
      </collision>
      <inertial>
      <origin xyz="0.0 0.0 0.196" rpy="0 0 0" />
      <mass value="2.2750" />
      <inertia ixx="0.0311796" ixy="0.0" ixz="0.0"
        iyy="0.0311796" iyz="0.0"
        izz="0.004095" />
      </inertial>
    </link>

    <joint name="ur5_wrist_1_joint" type="revolute">
      <parent link="ur5_forearm_link" />
      <child link = "ur5_wrist_1_link" />
      <origin xyz="0.0 0.0 0.392" rpy="0.0 1.570796 0.0" />
      <axis xyz="0 1 0" />
      <limit lower="-6.28" upper="6.28" effort="28.0" velocity="6.28"/>
    </joint>

    <link name="ur5_wrist_1_link">
      <visual>
        <geometry>
          <mesh filename="./meshes/ur5e/visual/wrist1.dae" />
        </geometry>
        <material name="LightGrey">
          <color rgba="0.7 0.7 0.7 1.0"/>
        </material>
      </visual>
      <collision>
        <geometry>
          <mesh filename="./meshes/ur5e/collision/wrist1.stl" />
        </geometry>
      </collision>
      <inertial>
      <origin xyz="0.0 0.127 0.0" rpy="0 0 0" />
      <mass value="1.2190" />
      <inertia ixx="0.0025599" ixy="0.0" ixz="0.0"
        iyy="0.0025599" iyz="0.0"
        izz="0.0021942" />
      </inertial>
    </link>

    <joint name="ur5_wrist_2_joint" type="revolute">
      <parent link="ur5_wrist_1_link" />
      <child link = "ur5_wrist_2_link" />
      <origin xyz="0.0 0.127 0.0" rpy="0.0 0.0 0.0" />
      <axis xyz="0 0 1" />
      <limit lower="-6.28" upper="6.28" effort="28.0" velocity="6.28"/>
    </joint>

    <link name="ur5_wrist_2_link">
      <visual>
        <geometry>
          <mesh filename="./meshes/ur5e/visual/wrist2.dae" />
        </geometry>
        <material name="LightGrey">
          <color rgba="0.7 0.7 0.7 1.0"/>
        </material>
      </visual>
      <collision>
        <geometry>
          <mesh filename="./meshes/ur5e/collision/wrist2.stl" />
        </geometry>
      </collision>
      <inertial>
      <origin xyz="0.0 0.0 0.100" rpy="0 0 0" />
      <mass value="1.2190" />
      <inertia ixx="0.0025599" ixy="0.0" ixz="0.0"
        iyy="0.0025599" iyz="0.0"
        izz="0.0021942" />
      </inertial>
    </link>

    <joint name="ur5_wrist_3_joint" type="revolute">
      <parent link="ur5_wrist_2_link" />
      <child link = "ur5_wrist_3_link" />
      <origin xyz="0.0 0.0 0.100" rpy="0.0 0.0 0.0" />
      <axis xyz="0 1 0" />
      <limit lower="-6.28" upper="6.28" effort="28.0" velocity="6.28"/>
    </joint>

    <link name="ur5_wrist_3_link">
      <visual>
        <geometry>
          <mesh filename="./meshes/ur5e/visual/wrist3.dae" />
        </geometry>
        <material name="LightGrey">
          <color rgba="0.7 0.7 0.7 1.0"/>
        </material>
      </visual>
      <collision>
        <geometry>
          <mesh filename="./meshes/ur5e/collision/wrist3.stl" />
        </geometry>
      </collision>
      <inertial>
      <origin xyz="0.0 0.0771 0.0" rpy="1.570796 0 0" />
      <mass value="0.1879" />
      <inertia ixx="0.0000989" ixy="0.0" ixz="0.0"
        iyy="0.0000989" iyz="0.0"
        izz="0.0001321" />
      </inertial>
    </link>

    <joint name="ur5_ee_fixed_joint" type="fixed">
      <parent link="ur5_wrist_3_link" />
      <child link = "ur5_ee_link" />
      <origin xyz="0.0 0.100 0.0" rpy="0.0 0.0 1.570796" />
    </joint>

    <link name="ur5_ee_link">
      <collision>
        <geometry>
          <box size="0.01 0.01 0.01"/>
        </geometry>
        <origin rpy="0 0 0" xyz="-0.01 0 0"/>
      </collision>
    </link>



    <!-- ROS base_link to UR 'Base' Coordinates transform -->
    <link name="ur5_base"/>
    <joint name="ur5_base_link-base_fixed_joint" type="fixed">
      <origin xyz="0 0 0" rpy="0 0 -3.14159"/>
      <parent link="ur5_base_link"/>
      <child link="ur5_base"/>
    </joint>

    <!-- Frame coincident with all-zeros TCP on UR controller -->
    <link name="ur5_tool0"/>
    
    <joint name="ur5_wrist_3_link-tool0_fixed_joint" type="fixed">
      <origin xyz="0 0.100 0" rpy="-1.570796 0 0"/>
      <parent link="ur5_wrist_3_link"/>
      <child link="ur5_tool0"/>
    </joint>

</robot>
